#VRML_SIM R2019a utf8
WorldInfo {
}
Viewpoint {
  orientation -0.030718921160128865 -0.8376975115065185 -0.5452698663034151 3.058441860857372
  position 0.44022801757538454 5.798545038645508 -1.4777623390960084
}
TexturedBackground {
}
TexturedBackgroundLight {
}
Floor {
}
Robot {
  translation 0.4900000000000002 0.07999999999999997 0.7400000000000002
  children [
    DEF BODY Group {
      children [
        DEF S_ROBOT Shape {
          appearance PBRAppearance {
            baseColor 0.9372549019607843 0.1607843137254902 0.1607843137254902
          }
          geometry DEF G_BODY Box {
            size 0.25 0.07 0.1
          }
        }
        DEF T_1 Transform {
          translation 0.11 -0.05 0
          children [
            Shape {
              appearance PBRAppearance {
                roughness 1
                metalness 0
              }
              geometry Sphere {
                radius 0.015
              }
            }
          ]
        }
      ]
    }
    DEF WHEEL1 HingeJoint {
      jointParameters HingeJointParameters {
        axis 0 0 1
        anchor -0.05 0 0.06
      }
      device [
        PositionSensor {
          name "encoder1"
        }
        RotationalMotor {
          name "motor_right"
          maxVelocity 6.66
        }
      ]
      endPoint DEF WHEEL1 Solid {
        translation -0.05 0 0.06
        rotation -1 0 0 1.57
        children [
          DEF S_WHEEL1 Shape {
            appearance PBRAppearance {
              baseColor 0 0 0
              roughness 1
              metalness 0
            }
            geometry DEF G_WHEEL1 Cylinder {
              height 0.02
              radius 0.075
            }
          }
        ]
        boundingObject USE G_WHEEL1
        physics Physics {
        }
      }
    }
    DEF WHEEL2 HingeJoint {
      jointParameters HingeJointParameters {
        axis 0 0 1
        anchor -0.05 0 -0.06
      }
      device [
        PositionSensor {
          name "encoder2"
        }
        RotationalMotor {
          name "motor_left"
          maxVelocity 6.66
        }
      ]
      endPoint DEF WHEEL2 Solid {
        translation -0.05 0 -0.06
        rotation -1 0 0 1.57
        children [
          DEF S_WHEEL2 Shape {
            appearance PBRAppearance {
              baseColor 0 0 0
              roughness 1
              metalness 0
            }
            geometry DEF G_WHEEL2 Cylinder {
              height 0.02
              radius 0.075
            }
          }
        ]
        name "solid(1)"
        boundingObject USE G_WHEEL2
        physics Physics {
        }
      }
    }
    DistanceSensor {
      translation 0.125 0 0
      children [
        DEF S_SENSOR Shape {
          appearance PBRAppearance {
            baseColor 0.1803921568627451 0.20392156862745098 0.21176470588235294
          }
          geometry DEF G_BOX_SENSOR Box {
            size 0.02 0.01 0.01
          }
        }
      ]
      name "distance_sensor"
      lookupTable [
        0 0 0
        0.05 0 0
        2 1660 0
      ]
      resolution 1
    }
  ]
  boundingObject USE BODY
  physics Physics {
  }
  controller "robot1_Navarro_Esther"
}
DEF OBSTACLE1 Solid {
  translation 1.0400000000000003 0.05999999223226717 0.2900000053223359
  rotation 0.9999999999999999 0 0 4.712388966
  children [
    DEF S_OBSTACLE1 Shape {
      appearance PBRAppearance {
        baseColor 0.45098039215686275 0.8235294117647058 0.08627450980392157
      }
      geometry DEF G_OBSTACLE1 Box {
        size 0.2 2 0.1
      }
    }
  ]
  name "solid(1)"
  boundingObject USE G_OBSTACLE1
  physics Physics {
  }
}
DEF OBSTACLE2 Solid {
  translation -1.4299999999999995 0.05999999223226717 0.2900000053223359
  rotation 0.9999999999999999 0 0 4.712388966
  children [
    DEF S_OBSTACLE2 Shape {
      appearance PBRAppearance {
        baseColor 0.45098039215686275 0.8235294117647058 0.08627450980392157
      }
      geometry DEF G_OBSTACLE2 Box {
        size 0.2 2 0.1
      }
    }
  ]
  name "solid(2)"
  boundingObject USE G_OBSTACLE2
  physics Physics {
  }
}
DEF OBSTACLE3 Solid {
  translation -0.320000001198724 0.0500000021577034 1.5000000000000009
  rotation 0 0 1 1.5707963220000003
  children [
    DEF S_OBSTACLE3 Shape {
      appearance PBRAppearance {
        baseColor 0.9607843137254902 0.4745098039215686 0
      }
      geometry DEF G_OBSTACLE3 Box {
        size 0.1 2 0.2
      }
    }
  ]
  name "solid(6)"
  boundingObject USE G_OBSTACLE3
  physics Physics {
  }
}
DEF OBSTACLE4 Solid {
  translation -0.12000000914973001 0.127982614089801 -0.8934028643067365
  rotation 0.5773502585112239 0.5773502686827361 -0.5773502803749172 2.0943950944240464
  children [
    DEF S_OBSTACLE4 Shape {
      appearance PBRAppearance {
        baseColor 0.9607843137254902 0.4745098039215686 0
      }
      geometry DEF G_OBSTACLE4 Box {
        size 0.2 2 0.1
      }
    }
  ]
  name "solid(7)"
  boundingObject USE G_OBSTACLE4
  physics Physics {
  }
}
