#VRML_SIM R2019a utf8
WorldInfo {
}
Viewpoint {
  orientation 0.3110250247998418 0.9137480833507228 0.2613960101477034 4.772915868729547
  position -1.8832895862581958 1.415789019244962 0.7985124120297221
}
TexturedBackground {
}
TexturedBackgroundLight {
}
Floor {
}
Robot {
  translation 0.4900000000000002 0.07999999999999997 0.1
  children [
    DEF BODY Group {
      children [
        DEF S_ROBOT Shape {
          appearance PBRAppearance {
            baseColor 0.9372549019607843 0.1607843137254902 0.1607843137254902
          }
          geometry DEF G_BODY Box {
            size 0.25 0.07 0.1
          }
        }
        DEF T_1 Transform {
          translation 0.11 -0.05 0
          children [
            Shape {
              appearance PBRAppearance {
                roughness 1
                metalness 0
              }
              geometry Sphere {
                radius 0.015
              }
            }
          ]
        }
      ]
    }
    DEF WHEEL1 HingeJoint {
      jointParameters HingeJointParameters {
        axis 0 0 1
        anchor -0.05 0 0.06
      }
      device [
        PositionSensor {
          name "encoder1"
        }
        RotationalMotor {
          name "motor_right"
          maxVelocity 6.66
        }
      ]
      endPoint DEF WHEEL1 Solid {
        translation -0.05 0 0.06
        rotation -1 0 0 1.57
        children [
          DEF S_WHEEL1 Shape {
            appearance PBRAppearance {
              baseColor 0 0 0
              roughness 1
              metalness 0
            }
            geometry DEF G_WHEEL1 Cylinder {
              height 0.02
              radius 0.075
            }
          }
        ]
        boundingObject USE G_WHEEL1
        physics Physics {
        }
      }
    }
    DEF WHEEL2 HingeJoint {
      jointParameters HingeJointParameters {
        axis 0 0 1
        anchor -0.05 0 -0.06
      }
      device [
        PositionSensor {
          name "encoder2"
        }
        RotationalMotor {
          name "motor_left"
          maxVelocity 6.66
        }
      ]
      endPoint DEF WHEEL2 Solid {
        translation -0.05 0 -0.06
        rotation -1 0 0 1.57
        children [
          DEF S_WHEEL2 Shape {
            appearance PBRAppearance {
              baseColor 0 0 0
              roughness 1
              metalness 0
            }
            geometry DEF G_WHEEL2 Cylinder {
              height 0.02
              radius 0.075
            }
          }
        ]
        name "solid(1)"
        boundingObject USE G_WHEEL2
        physics Physics {
        }
      }
    }
    DistanceSensor {
      translation 0.125 0 0
      children [
        DEF S_SENSOR Shape {
          appearance PBRAppearance {
            baseColor 0.1803921568627451 0.20392156862745098 0.21176470588235294
          }
          geometry DEF G_BOX_SENSOR Box {
            size 0.02 0.01 0.01
          }
        }
      ]
      name "distance_sensor"
      lookupTable [
        0 0 0
        0.05 0 0
        2 1660 0
      ]
      resolution 1
    }
  ]
  boundingObject USE BODY
  physics Physics {
  }
  controller "robot1"
}
DEF OBSTACLE1 Solid {
  translation 0 0 0.11000000000000004
  children [
    DEF S_OBSTACLE1 Shape {
      appearance PBRAppearance {
        baseColor 0.20392156862745098 0.396078431372549 0.6431372549019608
      }
      geometry DEF G_OBSTACLE Box {
        size 0.2 0.4 0.2
      }
    }
  ]
}
DEF OBSTACLE2 Solid {
  translation 0.7900000000000001 0 0.83
  children [
    DEF S_OBSTACLE2 Shape {
      appearance PBRAppearance {
        baseColor 0.45098039215686275 0.8235294117647058 0.08627450980392157
      }
      geometry DEF G_OBSTACLE2 Box {
        size 0.2 0.4 0.2
      }
    }
  ]
  name "solid(1)"
}
DEF OBSTACLE3 Solid {
  translation 0.7900000000000001 0 -0.5999999999999999
  children [
    DEF S_OBSTACLE3 Shape {
      appearance PBRAppearance {
        baseColor 0.9294117647058824 0.8313725490196079 0
      }
      geometry DEF G_OBSTACLE3 Box {
        size 0.2 0.4 0.2
      }
    }
  ]
  name "solid(2)"
}
DEF OBSTACLE4 Solid {
  translation 1.4700000000000006 0 0.09000000000000019
  children [
    DEF S_OBSTACLE4 Shape {
      appearance PBRAppearance {
        baseColor 0.8 0 0
      }
      geometry DEF G_OBSTACLE3 Box {
        size 0.2 0.4 0.2
      }
    }
  ]
  name "solid(3)"
}
