#VRML_SIM R2019a utf8
WorldInfo {
}
Viewpoint {
  orientation 0.048121052240531655 0.9786343999456708 0.19989766275332152 3.573963642042692
  position -0.7534737608725568 1.2139550587163266 -1.3706392381563608
}
TexturedBackground {
}
TexturedBackgroundLight {
}
Floor {
}
Robot {
  translation 0.1 0.07999999999999997 0.1
  children [
    DEF BODY Group {
      children [
        DEF S_ROBOT Shape {
          appearance PBRAppearance {
            baseColor 0.9372549019607843 0.1607843137254902 0.1607843137254902
          }
          geometry DEF G_BODY Box {
            size 0.25 0.07 0.1
          }
        }
        DEF T_1 Transform {
          translation 0.11 -0.05 0
          children [
            Shape {
              appearance PBRAppearance {
                roughness 1
                metalness 0
              }
              geometry Sphere {
                radius 0.015
              }
            }
          ]
        }
      ]
    }
    DEF WHEEL1 HingeJoint {
      jointParameters HingeJointParameters {
        axis 0 0 1
        anchor -0.05 0 0.06
      }
      device [
        PositionSensor {
          name "encoder1"
        }
        RotationalMotor {
          name "motor_right"
          maxVelocity 6.66
        }
      ]
      endPoint DEF WHEEL1 Solid {
        translation -0.05 0 0.06
        rotation -1 0 0 1.57
        children [
          DEF S_WHEEL1 Shape {
            appearance PBRAppearance {
              baseColor 0 0 0
              roughness 1
              metalness 0
            }
            geometry DEF G_WHEEL1 Cylinder {
              height 0.02
              radius 0.075
            }
          }
        ]
        boundingObject USE G_WHEEL1
        physics Physics {
        }
      }
    }
    DEF WHEEL2 HingeJoint {
      jointParameters HingeJointParameters {
        axis 0 0 1
        anchor -0.05 0 -0.06
      }
      device [
        PositionSensor {
          name "encoder2"
        }
        RotationalMotor {
          name "motor_left"
          maxVelocity 6.66
        }
      ]
      endPoint DEF WHEEL2 Solid {
        translation -0.05 0 -0.06
        rotation -1 0 0 1.57
        children [
          DEF S_WHEEL2 Shape {
            appearance PBRAppearance {
              baseColor 0 0 0
              roughness 1
              metalness 0
            }
            geometry DEF G_WHEEL2 Cylinder {
              height 0.02
              radius 0.075
            }
          }
        ]
        name "solid(1)"
        boundingObject USE G_WHEEL2
        physics Physics {
        }
      }
    }
    DistanceSensor {
      translation 0.125 0 0
      children [
        DEF S_SENSOR Shape {
          appearance PBRAppearance {
            baseColor 0.1803921568627451 0.20392156862745098 0.21176470588235294
          }
          geometry DEF G_BOX_SENSOR Box {
            size 0.02 0.01 0.01
          }
        }
      ]
      name "distance_sensor"
      lookupTable [
        0 0 0
        0.05 0 0
        2 1660 0
      ]
      resolution 1
    }
  ]
  boundingObject USE BODY
  physics Physics {
  }
  controller "robot1"
}
